# main.py 运行时错误分析报告

## 错误概述

**错误信息**: `can't convert type 'NoneType' to numerator/denominator`

**发生位置**: 训练进行到第300步时，在进度监控和内存监控系统中

**错误类型**: 类型转换错误

## 根本原因分析

### 1. 问题根源
错误发生的根本原因是在训练过程中，某些回调函数接收到了 `None` 值，而代码试图将这些 `None` 值转换为数值类型（如 `float` 或 `int`）。

### 2. 具体触发点
- **进度监控器** (`src/progress_monitor.py`): 在 `update_progress` 方法中，`epoch`、`step`、`loss` 或 `learning_rate` 参数可能为 `None`
- **训练引擎回调** (`src/training_engine.py`): 在各种回调函数中，`state.epoch` 可能为 `None`
- **进度报告生成**: 在生成训练摘要时，尝试将 `None` 值序列化为 JSON

### 3. 错误传播路径
```
训练器回调 → state.epoch = None → progress_monitor.update_progress() → 
类型转换失败 → "can't convert type 'NoneType' to numerator/denominator"
```

## 修复方案

### 1. 已实施的修复

#### A. 进度监控器修复 (`src/progress_monitor.py`)
```python
# 修复前
self.current_epoch = epoch
self.current_step = step
self.current_loss = loss
self.current_lr = learning_rate

# 修复后
self.current_epoch = float(epoch) if epoch is not None else 0.0
self.current_step = int(step) if step is not None else 0
self.current_loss = float(loss) if loss is not None else 0.0
self.current_lr = float(learning_rate) if learning_rate is not None else 0.0
```

#### B. 训练引擎回调修复 (`src/training_engine.py`)
```python
# 修复前
epoch = logs.get("epoch", 0)

# 修复后
epoch = logs.get("epoch", 0)
try:
    epoch = float(epoch) if epoch is not None else 0.0
except (TypeError, ValueError):
    epoch = 0.0
```

#### C. 进度快照生成修复
```python
# 修复前
epoch=self.current_epoch,

# 修复后
epoch=float(self.current_epoch) if self.current_epoch is not None else 0.0,
```

### 2. 修复效果验证

通过 `test_fix.py` 脚本验证了以下场景：
- ✅ `None` 值处理
- ✅ 正常数值处理
- ✅ 字符串数值转换
- ✅ 回调函数异常处理

## 预防措施

### 1. 类型安全检查
在所有数值转换处添加了类型检查和默认值处理。

### 2. 异常处理
在关键的类型转换点添加了 try-catch 块。

### 3. 日志记录
增强了错误日志记录，便于未来问题诊断。

## 建议的后续改进

### 1. 代码层面
- 考虑使用类型注解和静态类型检查工具（如 mypy）
- 实施更严格的输入验证
- 添加单元测试覆盖边界情况

### 2. 监控层面
- 增加更详细的训练状态监控
- 实施早期警告系统检测异常值

### 3. 文档层面
- 更新API文档，明确参数类型要求
- 添加错误处理最佳实践指南

## 使用说明

### 1. 应用修复
修复已自动应用到以下文件：
- `src/progress_monitor.py` (备份: `src/progress_monitor.py.backup`)
- `src/training_engine.py` (备份: `src/training_engine.py.backup`)

### 2. 重新运行训练
现在可以安全地重新运行训练：
```bash
uv run python main.py
```

### 3. 监控建议
在重新运行时，注意观察：
- 进度监控是否正常显示
- 内存使用是否稳定
- 是否还有其他类型转换错误

## 总结

这个错误是由于训练过程中的状态值可能为 `None`，而代码没有适当处理这种情况导致的。通过添加类型安全检查和默认值处理，问题已得到解决。修复后的代码更加健壮，能够处理各种边界情况。

**修复状态**: ✅ 已完成  
**测试状态**: ✅ 已验证  
**建议操作**: 重新运行 `main.py` 进行训练
